2019-11-02 20:17:15,210 ERROR: Exception on /update_scores [POST] [in /Users/gabefoley/Dropbox/Code/Python_Workspace/popchoose/venv/lib/python3.6/site-packages/flask/app.py:1891]
Traceback (most recent call last):
  File "/Users/gabefoley/Dropbox/Code/Python_Workspace/popchoose/venv/lib/python3.6/site-packages/flask/app.py", line 2446, in wsgi_app
    response = self.full_dispatch_request()
  File "/Users/gabefoley/Dropbox/Code/Python_Workspace/popchoose/venv/lib/python3.6/site-packages/flask/app.py", line 1951, in full_dispatch_request
    rv = self.handle_user_exception(e)
  File "/Users/gabefoley/Dropbox/Code/Python_Workspace/popchoose/venv/lib/python3.6/site-packages/flask/app.py", line 1820, in handle_user_exception
    reraise(exc_type, exc_value, tb)
  File "/Users/gabefoley/Dropbox/Code/Python_Workspace/popchoose/venv/lib/python3.6/site-packages/flask/_compat.py", line 39, in reraise
    raise value
  File "/Users/gabefoley/Dropbox/Code/Python_Workspace/popchoose/venv/lib/python3.6/site-packages/flask/app.py", line 1949, in full_dispatch_request
    rv = self.dispatch_request()
  File "/Users/gabefoley/Dropbox/Code/Python_Workspace/popchoose/venv/lib/python3.6/site-packages/flask/app.py", line 1935, in dispatch_request
    return self.view_functions[rule.endpoint](**req.view_args)
  File "/Users/gabefoley/Dropbox/Code/Python_Workspace/popchoose/app/routes.py", line 31, in update_scores
    database.update_matchup("_".join(sorted_ids), info['correct'])
  File "/Users/gabefoley/Dropbox/Code/Python_Workspace/popchoose/app/database.py", line 54, in update_matchup
    db.commit()
AttributeError: 'SQLAlchemy' object has no attribute 'commit'
2019-11-02 20:17:17,773 ERROR: Exception on /update_scores [POST] [in /Users/gabefoley/Dropbox/Code/Python_Workspace/popchoose/venv/lib/python3.6/site-packages/flask/app.py:1891]
Traceback (most recent call last):
  File "/Users/gabefoley/Dropbox/Code/Python_Workspace/popchoose/venv/lib/python3.6/site-packages/flask/app.py", line 2446, in wsgi_app
    response = self.full_dispatch_request()
  File "/Users/gabefoley/Dropbox/Code/Python_Workspace/popchoose/venv/lib/python3.6/site-packages/flask/app.py", line 1951, in full_dispatch_request
    rv = self.handle_user_exception(e)
  File "/Users/gabefoley/Dropbox/Code/Python_Workspace/popchoose/venv/lib/python3.6/site-packages/flask/app.py", line 1820, in handle_user_exception
    reraise(exc_type, exc_value, tb)
  File "/Users/gabefoley/Dropbox/Code/Python_Workspace/popchoose/venv/lib/python3.6/site-packages/flask/_compat.py", line 39, in reraise
    raise value
  File "/Users/gabefoley/Dropbox/Code/Python_Workspace/popchoose/venv/lib/python3.6/site-packages/flask/app.py", line 1949, in full_dispatch_request
    rv = self.dispatch_request()
  File "/Users/gabefoley/Dropbox/Code/Python_Workspace/popchoose/venv/lib/python3.6/site-packages/flask/app.py", line 1935, in dispatch_request
    return self.view_functions[rule.endpoint](**req.view_args)
  File "/Users/gabefoley/Dropbox/Code/Python_Workspace/popchoose/app/routes.py", line 31, in update_scores
    database.update_matchup("_".join(sorted_ids), info['correct'])
  File "/Users/gabefoley/Dropbox/Code/Python_Workspace/popchoose/app/database.py", line 54, in update_matchup
    db.commit()
AttributeError: 'SQLAlchemy' object has no attribute 'commit'
2019-11-02 20:17:20,620 ERROR: Exception on /update_scores [POST] [in /Users/gabefoley/Dropbox/Code/Python_Workspace/popchoose/venv/lib/python3.6/site-packages/flask/app.py:1891]
Traceback (most recent call last):
  File "/Users/gabefoley/Dropbox/Code/Python_Workspace/popchoose/venv/lib/python3.6/site-packages/flask/app.py", line 2446, in wsgi_app
    response = self.full_dispatch_request()
  File "/Users/gabefoley/Dropbox/Code/Python_Workspace/popchoose/venv/lib/python3.6/site-packages/flask/app.py", line 1951, in full_dispatch_request
    rv = self.handle_user_exception(e)
  File "/Users/gabefoley/Dropbox/Code/Python_Workspace/popchoose/venv/lib/python3.6/site-packages/flask/app.py", line 1820, in handle_user_exception
    reraise(exc_type, exc_value, tb)
  File "/Users/gabefoley/Dropbox/Code/Python_Workspace/popchoose/venv/lib/python3.6/site-packages/flask/_compat.py", line 39, in reraise
    raise value
  File "/Users/gabefoley/Dropbox/Code/Python_Workspace/popchoose/venv/lib/python3.6/site-packages/flask/app.py", line 1949, in full_dispatch_request
    rv = self.dispatch_request()
  File "/Users/gabefoley/Dropbox/Code/Python_Workspace/popchoose/venv/lib/python3.6/site-packages/flask/app.py", line 1935, in dispatch_request
    return self.view_functions[rule.endpoint](**req.view_args)
  File "/Users/gabefoley/Dropbox/Code/Python_Workspace/popchoose/app/routes.py", line 31, in update_scores
    database.update_matchup("_".join(sorted_ids), info['correct'])
  File "/Users/gabefoley/Dropbox/Code/Python_Workspace/popchoose/app/database.py", line 54, in update_matchup
    db.commit()
AttributeError: 'SQLAlchemy' object has no attribute 'commit'
2019-11-02 20:17:26,066 ERROR: Exception on /update_scores [POST] [in /Users/gabefoley/Dropbox/Code/Python_Workspace/popchoose/venv/lib/python3.6/site-packages/flask/app.py:1891]
Traceback (most recent call last):
  File "/Users/gabefoley/Dropbox/Code/Python_Workspace/popchoose/venv/lib/python3.6/site-packages/flask/app.py", line 2446, in wsgi_app
    response = self.full_dispatch_request()
  File "/Users/gabefoley/Dropbox/Code/Python_Workspace/popchoose/venv/lib/python3.6/site-packages/flask/app.py", line 1951, in full_dispatch_request
    rv = self.handle_user_exception(e)
  File "/Users/gabefoley/Dropbox/Code/Python_Workspace/popchoose/venv/lib/python3.6/site-packages/flask/app.py", line 1820, in handle_user_exception
    reraise(exc_type, exc_value, tb)
  File "/Users/gabefoley/Dropbox/Code/Python_Workspace/popchoose/venv/lib/python3.6/site-packages/flask/_compat.py", line 39, in reraise
    raise value
  File "/Users/gabefoley/Dropbox/Code/Python_Workspace/popchoose/venv/lib/python3.6/site-packages/flask/app.py", line 1949, in full_dispatch_request
    rv = self.dispatch_request()
  File "/Users/gabefoley/Dropbox/Code/Python_Workspace/popchoose/venv/lib/python3.6/site-packages/flask/app.py", line 1935, in dispatch_request
    return self.view_functions[rule.endpoint](**req.view_args)
  File "/Users/gabefoley/Dropbox/Code/Python_Workspace/popchoose/app/routes.py", line 31, in update_scores
    database.update_matchup("_".join(sorted_ids), info['correct'])
  File "/Users/gabefoley/Dropbox/Code/Python_Workspace/popchoose/app/database.py", line 54, in update_matchup
    db.commit()
AttributeError: 'SQLAlchemy' object has no attribute 'commit'
2019-11-02 20:17:28,885 ERROR: Exception on /update_scores [POST] [in /Users/gabefoley/Dropbox/Code/Python_Workspace/popchoose/venv/lib/python3.6/site-packages/flask/app.py:1891]
Traceback (most recent call last):
  File "/Users/gabefoley/Dropbox/Code/Python_Workspace/popchoose/venv/lib/python3.6/site-packages/flask/app.py", line 2446, in wsgi_app
    response = self.full_dispatch_request()
  File "/Users/gabefoley/Dropbox/Code/Python_Workspace/popchoose/venv/lib/python3.6/site-packages/flask/app.py", line 1951, in full_dispatch_request
    rv = self.handle_user_exception(e)
  File "/Users/gabefoley/Dropbox/Code/Python_Workspace/popchoose/venv/lib/python3.6/site-packages/flask/app.py", line 1820, in handle_user_exception
    reraise(exc_type, exc_value, tb)
  File "/Users/gabefoley/Dropbox/Code/Python_Workspace/popchoose/venv/lib/python3.6/site-packages/flask/_compat.py", line 39, in reraise
    raise value
  File "/Users/gabefoley/Dropbox/Code/Python_Workspace/popchoose/venv/lib/python3.6/site-packages/flask/app.py", line 1949, in full_dispatch_request
    rv = self.dispatch_request()
  File "/Users/gabefoley/Dropbox/Code/Python_Workspace/popchoose/venv/lib/python3.6/site-packages/flask/app.py", line 1935, in dispatch_request
    return self.view_functions[rule.endpoint](**req.view_args)
  File "/Users/gabefoley/Dropbox/Code/Python_Workspace/popchoose/app/routes.py", line 31, in update_scores
    database.update_matchup("_".join(sorted_ids), info['correct'])
  File "/Users/gabefoley/Dropbox/Code/Python_Workspace/popchoose/app/database.py", line 54, in update_matchup
    db.commit()
AttributeError: 'SQLAlchemy' object has no attribute 'commit'
2019-11-02 20:17:31,751 ERROR: Exception on /update_scores [POST] [in /Users/gabefoley/Dropbox/Code/Python_Workspace/popchoose/venv/lib/python3.6/site-packages/flask/app.py:1891]
Traceback (most recent call last):
  File "/Users/gabefoley/Dropbox/Code/Python_Workspace/popchoose/venv/lib/python3.6/site-packages/flask/app.py", line 2446, in wsgi_app
    response = self.full_dispatch_request()
  File "/Users/gabefoley/Dropbox/Code/Python_Workspace/popchoose/venv/lib/python3.6/site-packages/flask/app.py", line 1951, in full_dispatch_request
    rv = self.handle_user_exception(e)
  File "/Users/gabefoley/Dropbox/Code/Python_Workspace/popchoose/venv/lib/python3.6/site-packages/flask/app.py", line 1820, in handle_user_exception
    reraise(exc_type, exc_value, tb)
  File "/Users/gabefoley/Dropbox/Code/Python_Workspace/popchoose/venv/lib/python3.6/site-packages/flask/_compat.py", line 39, in reraise
    raise value
  File "/Users/gabefoley/Dropbox/Code/Python_Workspace/popchoose/venv/lib/python3.6/site-packages/flask/app.py", line 1949, in full_dispatch_request
    rv = self.dispatch_request()
  File "/Users/gabefoley/Dropbox/Code/Python_Workspace/popchoose/venv/lib/python3.6/site-packages/flask/app.py", line 1935, in dispatch_request
    return self.view_functions[rule.endpoint](**req.view_args)
  File "/Users/gabefoley/Dropbox/Code/Python_Workspace/popchoose/app/routes.py", line 31, in update_scores
    database.update_matchup("_".join(sorted_ids), info['correct'])
  File "/Users/gabefoley/Dropbox/Code/Python_Workspace/popchoose/app/database.py", line 54, in update_matchup
    db.commit()
AttributeError: 'SQLAlchemy' object has no attribute 'commit'
