2019-11-02 20:17:33,834 ERROR: Exception on /update_scores [POST] [in /Users/gabefoley/Dropbox/Code/Python_Workspace/popchoose/venv/lib/python3.6/site-packages/flask/app.py:1891]
Traceback (most recent call last):
  File "/Users/gabefoley/Dropbox/Code/Python_Workspace/popchoose/venv/lib/python3.6/site-packages/flask/app.py", line 2446, in wsgi_app
    response = self.full_dispatch_request()
  File "/Users/gabefoley/Dropbox/Code/Python_Workspace/popchoose/venv/lib/python3.6/site-packages/flask/app.py", line 1951, in full_dispatch_request
    rv = self.handle_user_exception(e)
  File "/Users/gabefoley/Dropbox/Code/Python_Workspace/popchoose/venv/lib/python3.6/site-packages/flask/app.py", line 1820, in handle_user_exception
    reraise(exc_type, exc_value, tb)
  File "/Users/gabefoley/Dropbox/Code/Python_Workspace/popchoose/venv/lib/python3.6/site-packages/flask/_compat.py", line 39, in reraise
    raise value
  File "/Users/gabefoley/Dropbox/Code/Python_Workspace/popchoose/venv/lib/python3.6/site-packages/flask/app.py", line 1949, in full_dispatch_request
    rv = self.dispatch_request()
  File "/Users/gabefoley/Dropbox/Code/Python_Workspace/popchoose/venv/lib/python3.6/site-packages/flask/app.py", line 1935, in dispatch_request
    return self.view_functions[rule.endpoint](**req.view_args)
  File "/Users/gabefoley/Dropbox/Code/Python_Workspace/popchoose/app/routes.py", line 31, in update_scores
    database.update_matchup("_".join(sorted_ids), info['correct'])
  File "/Users/gabefoley/Dropbox/Code/Python_Workspace/popchoose/app/database.py", line 54, in update_matchup
    db.commit()
AttributeError: 'SQLAlchemy' object has no attribute 'commit'
2019-11-02 20:17:52,978 ERROR: Exception on /update_scores [POST] [in /Users/gabefoley/Dropbox/Code/Python_Workspace/popchoose/venv/lib/python3.6/site-packages/flask/app.py:1891]
Traceback (most recent call last):
  File "/Users/gabefoley/Dropbox/Code/Python_Workspace/popchoose/venv/lib/python3.6/site-packages/flask/app.py", line 2446, in wsgi_app
    response = self.full_dispatch_request()
  File "/Users/gabefoley/Dropbox/Code/Python_Workspace/popchoose/venv/lib/python3.6/site-packages/flask/app.py", line 1951, in full_dispatch_request
    rv = self.handle_user_exception(e)
  File "/Users/gabefoley/Dropbox/Code/Python_Workspace/popchoose/venv/lib/python3.6/site-packages/flask/app.py", line 1820, in handle_user_exception
    reraise(exc_type, exc_value, tb)
  File "/Users/gabefoley/Dropbox/Code/Python_Workspace/popchoose/venv/lib/python3.6/site-packages/flask/_compat.py", line 39, in reraise
    raise value
  File "/Users/gabefoley/Dropbox/Code/Python_Workspace/popchoose/venv/lib/python3.6/site-packages/flask/app.py", line 1949, in full_dispatch_request
    rv = self.dispatch_request()
  File "/Users/gabefoley/Dropbox/Code/Python_Workspace/popchoose/venv/lib/python3.6/site-packages/flask/app.py", line 1935, in dispatch_request
    return self.view_functions[rule.endpoint](**req.view_args)
  File "/Users/gabefoley/Dropbox/Code/Python_Workspace/popchoose/app/routes.py", line 31, in update_scores
    database.update_matchup("_".join(sorted_ids), info['correct'])
  File "/Users/gabefoley/Dropbox/Code/Python_Workspace/popchoose/app/database.py", line 54, in update_matchup
    db.commit()
AttributeError: 'SQLAlchemy' object has no attribute 'commit'
2019-11-02 20:18:51,468 INFO: Popchoose startup [in /Users/gabefoley/Dropbox/Code/Python_Workspace/popchoose/app/__init__.py:34]
2019-11-02 20:19:05,484 ERROR: Exception on /update_scores [POST] [in /Users/gabefoley/Dropbox/Code/Python_Workspace/popchoose/venv/lib/python3.6/site-packages/flask/app.py:1891]
Traceback (most recent call last):
  File "/Users/gabefoley/Dropbox/Code/Python_Workspace/popchoose/venv/lib/python3.6/site-packages/flask/app.py", line 2446, in wsgi_app
    response = self.full_dispatch_request()
  File "/Users/gabefoley/Dropbox/Code/Python_Workspace/popchoose/venv/lib/python3.6/site-packages/flask/app.py", line 1952, in full_dispatch_request
    return self.finalize_request(rv)
  File "/Users/gabefoley/Dropbox/Code/Python_Workspace/popchoose/venv/lib/python3.6/site-packages/flask/app.py", line 1967, in finalize_request
    response = self.make_response(rv)
  File "/Users/gabefoley/Dropbox/Code/Python_Workspace/popchoose/venv/lib/python3.6/site-packages/flask/app.py", line 2097, in make_response
    "The view function did not return a valid response. The"
TypeError: The view function did not return a valid response. The function either returned None or ended without a return statement.
2019-11-02 20:20:02,173 INFO: Popchoose startup [in /Users/gabefoley/Dropbox/Code/Python_Workspace/popchoose/app/__init__.py:34]
2019-11-02 20:23:29,716 INFO: Popchoose startup [in /Users/gabefoley/Dropbox/Code/Python_Workspace/popchoose/app/__init__.py:34]
2019-11-02 20:23:40,249 ERROR: Exception on /index [GET] [in /Users/gabefoley/Dropbox/Code/Python_Workspace/popchoose/venv/lib/python3.6/site-packages/flask/app.py:1891]
Traceback (most recent call last):
  File "/Users/gabefoley/Dropbox/Code/Python_Workspace/popchoose/venv/lib/python3.6/site-packages/flask/app.py", line 2446, in wsgi_app
    response = self.full_dispatch_request()
  File "/Users/gabefoley/Dropbox/Code/Python_Workspace/popchoose/venv/lib/python3.6/site-packages/flask/app.py", line 1951, in full_dispatch_request
    rv = self.handle_user_exception(e)
  File "/Users/gabefoley/Dropbox/Code/Python_Workspace/popchoose/venv/lib/python3.6/site-packages/flask/app.py", line 1820, in handle_user_exception
    reraise(exc_type, exc_value, tb)
  File "/Users/gabefoley/Dropbox/Code/Python_Workspace/popchoose/venv/lib/python3.6/site-packages/flask/_compat.py", line 39, in reraise
    raise value
  File "/Users/gabefoley/Dropbox/Code/Python_Workspace/popchoose/venv/lib/python3.6/site-packages/flask/app.py", line 1949, in full_dispatch_request
    rv = self.dispatch_request()
  File "/Users/gabefoley/Dropbox/Code/Python_Workspace/popchoose/venv/lib/python3.6/site-packages/flask/app.py", line 1935, in dispatch_request
    return self.view_functions[rule.endpoint](**req.view_args)
  File "/Users/gabefoley/Dropbox/Code/Python_Workspace/popchoose/app/routes.py", line 9, in index
    artists = database.get_artists()
  File "/Users/gabefoley/Dropbox/Code/Python_Workspace/popchoose/app/database.py", line 13, in get_artists
    a2 = db.session.query(Artist).filter(Artist.popularity != a1.popularity).order_by(func.rand()).first()
AttributeError: 'NoneType' object has no attribute 'popularity'
2019-11-02 20:25:34,784 INFO: Popchoose startup [in /Users/gabefoley/Dropbox/Code/Python_Workspace/popchoose/app/__init__.py:34]
2019-11-02 20:26:15,064 ERROR: Exception on /index [GET] [in /Users/gabefoley/Dropbox/Code/Python_Workspace/popchoose/venv/lib/python3.6/site-packages/flask/app.py:1891]
Traceback (most recent call last):
  File "/Users/gabefoley/Dropbox/Code/Python_Workspace/popchoose/venv/lib/python3.6/site-packages/flask/app.py", line 2446, in wsgi_app
    response = self.full_dispatch_request()
  File "/Users/gabefoley/Dropbox/Code/Python_Workspace/popchoose/venv/lib/python3.6/site-packages/flask/app.py", line 1951, in full_dispatch_request
    rv = self.handle_user_exception(e)
  File "/Users/gabefoley/Dropbox/Code/Python_Workspace/popchoose/venv/lib/python3.6/site-packages/flask/app.py", line 1820, in handle_user_exception
    reraise(exc_type, exc_value, tb)
  File "/Users/gabefoley/Dropbox/Code/Python_Workspace/popchoose/venv/lib/python3.6/site-packages/flask/_compat.py", line 39, in reraise
    raise value
  File "/Users/gabefoley/Dropbox/Code/Python_Workspace/popchoose/venv/lib/python3.6/site-packages/flask/app.py", line 1949, in full_dispatch_request
    rv = self.dispatch_request()
  File "/Users/gabefoley/Dropbox/Code/Python_Workspace/popchoose/venv/lib/python3.6/site-packages/flask/app.py", line 1935, in dispatch_request
    return self.view_functions[rule.endpoint](**req.view_args)
  File "/Users/gabefoley/Dropbox/Code/Python_Workspace/popchoose/app/routes.py", line 22, in index
    matchup_text = database.get_matchup(joint_id)
  File "/Users/gabefoley/Dropbox/Code/Python_Workspace/popchoose/app/database.py", line 28, in get_matchup
    return f"This match up has been guessed correctly {query['correct']} out of a total {query['correct'] + query['incorrect']} times "
TypeError: 'MatchUp' object is not subscriptable
2019-11-02 20:28:10,548 INFO: Popchoose startup [in /Users/gabefoley/Dropbox/Code/Python_Workspace/popchoose/app/__init__.py:34]
2019-11-02 20:33:56,693 INFO: Popchoose startup [in /Users/gabefoley/Dropbox/Code/Python_Workspace/popchoose/app/__init__.py:34]
2019-11-02 20:39:58,261 INFO: Popchoose startup [in /Users/gabefoley/Dropbox/Code/Python_Workspace/popchoose/app/__init__.py:34]
2019-11-02 21:59:38,432 INFO: Popchoose startup [in /Users/gabefoley/Dropbox/Code/Python_Workspace/popchoose/app/__init__.py:34]
2019-11-02 22:00:58,812 INFO: Popchoose startup [in /Users/gabefoley/Dropbox/Code/Python_Workspace/popchoose/app/__init__.py:34]
2019-11-02 22:01:54,805 INFO: Popchoose startup [in /Users/gabefoley/Dropbox/Code/Python_Workspace/popchoose/app/__init__.py:34]
2019-11-02 22:03:59,623 INFO: Popchoose startup [in /Users/gabefoley/Dropbox/Code/Python_Workspace/popchoose/app/__init__.py:34]
2019-11-02 22:04:37,945 INFO: Popchoose startup [in /Users/gabefoley/Dropbox/Code/Python_Workspace/popchoose/app/__init__.py:34]
2019-11-02 22:16:43,591 INFO: Popchoose startup [in /Users/gabefoley/Dropbox/Code/Python_Workspace/popchoose/app/__init__.py:34]
2019-11-02 22:17:17,641 INFO: Popchoose startup [in /Users/gabefoley/Dropbox/Code/Python_Workspace/popchoose/app/__init__.py:34]
2019-11-02 22:28:42,932 INFO: Popchoose startup [in /Users/gabefoley/Dropbox/Code/Python_Workspace/popchoose/app/__init__.py:34]
2019-11-02 22:29:56,895 INFO: Popchoose startup [in /Users/gabefoley/Dropbox/Code/Python_Workspace/popchoose/app/__init__.py:34]
2019-11-02 22:31:57,603 INFO: Popchoose startup [in /Users/gabefoley/Dropbox/Code/Python_Workspace/popchoose/app/__init__.py:34]
2019-11-02 22:32:31,126 INFO: Popchoose startup [in /Users/gabefoley/Dropbox/Code/Python_Workspace/popchoose/app/__init__.py:34]
